Workbook

Sheet Config
B2: Configuration
B3: Yellow cells = user inputs
B4: Locker Dimensions | E4: Quantities | H4: Material Stock Size
B5: Model Type | C5: Model A | E5: Quantity Frames | F5: 100 | H5: Width (in) | I5: 60
B6: Locker Width (in) | C6: 9 | E6: Lockers per Frame | F6: Lockers | H6: Length (in) | I6: 96
B7: Locker Height (in) | C7: 96
B9: Output
B10: Total Sheets | C10: =ROUNDUP(Tables!Q27/Tables!D2,0) -> 17

Sheet Tables
B1: Width (in) | C1: Depth (in) | D1: Sqft (SQF)
A2: Stock Size | B2: =Config!I5 -> 60 | C2: =Config!I6 -> 96 | D2: =(B2*C2)/(12^2) -> 40 | M2: Column# | N2: 1 | O2: 2 | P2: 3 | Q2: 4 | R2: 5 | S2: 6 | T2: 7
K3: Lower Limit (in) | L3: Door Width | M3: Upper Limit (in) | N3: Model A | O3: Model Z | P3: Model B | Q3: Model C | R3: Model D | S3: Model E | T3: Model F
J4: Row# | N4: Door (SQF) | O4: Door (SQF) | P4: Door (SQF) | Q4: Door (SQF) | R4: Door (SQF) | S4: Door (SQF) | T4: Door (SQF)
J5: 1 | K5: =M4+0.00001 -> 1e-05 | M5: =$D$39 -> 4 | N5: =I59 -> 2.6666667 | O5: =I72 -> 1.3333333 | P5: =I85 -> 1.3333333 | Q5: =I98 -> 0.88888889 | R5: =I112 -> 0.66666667 | S5: =I126 -> 0.53333333 | T5: =I140 -> 0.44444444 | V5: =IF(AND($Q$18>=K5, $Q$18<=M5+0.00001), "Within Range", "Out of Range") -> Out of Range
J6: 2 | K6: =M5+0.00001 -> 4.00001 | M6: =$D$40 -> 5 | N6: =I60 -> 3.3333333 | O6: =I73 -> 1.6666667 | P6: =I86 -> 1.6666667 | Q6: =I99 -> 1.1111111 | R6: =I113 -> 0.83333333 | S6: =I127 -> 0.66666667 | T6: =I141 -> 0.55555556 | V6: =IF(AND($Q$18>=K6, $Q$18<=M6+0.00001), "Within Range", "Out of Range") -> Out of Range
J7: 3 | K7: =M6+0.00001 -> 5.00001 | M7: =$D$41 -> 6 | N7: =I61 -> 4 | O7: =I74 -> 2 | P7: =I87 -> 2 | Q7: =I100 -> 1.3333333 | R7: =I114 -> 1 | S7: =I128 -> 0.8 | T7: =I142 -> 0.66666667 | V7: =IF(AND($Q$18>=K7, $Q$18<=M7+0.00001), "Within Range", "Out of Range") -> Out of Range
J8: 4 | K8: =M7+0.00001 -> 6.00001 | M8: =$D$42 -> 6.6666667 | N8: =I62 -> 4.4444444 | O8: =I75 -> 2.2222222 | P8: =I88 -> 2.2222222 | Q8: =I101 -> 1.4814815 | R8: =I115 -> 1.1111111 | S8: =I129 -> 0.88888889 | T8: =I143 -> 0.74074074 | V8: =IF(AND($Q$18>=K8, $Q$18<=M8+0.00001), "Within Range", "Out of Range") -> Out of Range
J9: 5 | K9: =M8+0.00001 -> 6.6666767 | M9: =$D$43 -> 7.5 | N9: =I63 -> 5 | O9: =I76 -> 2.5 | P9: =I89 -> 2.5 | Q9: =I102 -> 1.6666667 | R9: =I116 -> 1.25 | S9: =I130 -> 1 | T9: =I144 -> 0.83333333 | V9: =IF(AND($Q$18>=K9, $Q$18<=M9+0.00001), "Within Range", "Out of Range") -> Out of Range
J10: 6 | K10: =M9+0.00001 -> 7.50001 | M10: =$D$44 -> 8.5714286 | N10: =I64 -> 5.7142857 | O10: =I77 -> 2.8571429 | P10: =I90 -> 2.8571429 | Q10: =I103 -> 1.9047619 | R10: =I117 -> 1.4285714 | S10: =I131 -> 1.1428571 | T10: =I145 -> 0.95238095 | V10: =IF(AND($Q$18>=K10, $Q$18<=M10+0.00001), "Within Range", "Out of Range") -> Out of Range
J11: 7 | K11: =M10+0.00001 -> 8.5714386 | M11: =$D$45 -> 10 | N11: =I65 -> 6.6666667 | O11: =I78 -> 3.3333333 | P11: =I91 -> 3.3333333 | Q11: =I104 -> 2.2222222 | R11: =I118 -> 1.6666667 | S11: =I132 -> 1.3333333 | T11: =I146 -> 1.1111111 | V11: =IF(AND($Q$18>=K11, $Q$18<=M11+0.00001), "Within Range", "Out of Range") -> Within Range
J12: 8 | K12: =M11+0.00001 -> 10.00001 | M12: =$D$46 -> 12 | N12: =I66 -> 8 | O12: =I79 -> 4 | P12: =I92 -> 4 | Q12: =I105 -> 2.6666667 | R12: =I119 -> 2 | S12: =I133 -> 1.6 | T12: =I147 -> 1.3333333 | V12: =IF(AND($Q$18>=K12, $Q$18<=M12+0.00001), "Within Range", "Out of Range") -> Out of Range
J13: 9 | K13: =M12+0.00001 -> 12.00001 | M13: =$D$47 -> 15 | N13: =I67 -> 10 | O13: =I80 -> 5 | P13: =I93 -> 5 | Q13: =I106 -> 3.3333333 | R13: =I120 -> 2.5 | S13: =I134 -> 2 | T13: =I148 -> 1.6666667 | V13: =IF(AND($Q$18>=K13, $Q$18<=M13+0.00001), "Within Range", "Out of Range") -> Out of Range
J14: 10 | K14: =M13+0.00001 -> 15.00001 | M14: =$D$48 -> 20 | N14: =I68 -> 13.333333 | O14: =I81 -> 6.6666667 | P14: =I94 -> 6.6666667 | Q14: =I107 -> 4.4444444 | R14: =I121 -> 3.3333333 | S14: =I135 -> 2.6666667 | T14: =I149 -> 2.2222222 | V14: =IF(AND($Q$18>=K14, $Q$18<=M14+0.00001), "Within Range", "Out of Range") -> Out of Range
J15: 11 | K15: =M14+0.00001 -> 20.00001 | M15: =$D$49 -> 30 | N15: =I69 -> 20 | O15: =I82 -> 10 | P15: =I95 -> 10 | Q15: =I108 -> 6.6666667 | R15: =I122 -> 5 | S15: =I136 -> 4 | T15: =I150 -> 3.3333333 | V15: =IF(AND($Q$18>=K15, $Q$18<=M15+0.00001), "Within Range", "Out of Range") -> Out of Range
J16: 12 | K16: =M15+0.00001 -> 30.00001 | M16: =$D$50 -> 60 | N16: =I70 -> 40 | O16: =I83 -> 20 | P16: =I96 -> 20 | Q16: =I109 -> 13.333333 | R16: =I123 -> 10 | S16: =I137 -> 8 | T16: =I151 -> 6.6666667 | V16: =IF(AND($Q$18>=K16, $Q$18<=M16+0.00001), "Within Range", "Out of Range") -> Out of Range
Q18: =Config!C6 -> 9 | R18: in
O19: Index Row = | Q19: {=_xlfn.IFS(V5="within range",J5,V6="within range",J6,V7="within range",J7,V8="within range",J8,V9="within range",J9,V10="within range",J10,V11="within range",J11,V12="within range",J12,V13="within range",J13,V14="within range",J14,V15="within range",J15,V16="within range",J16)} -> 7
O20: Model Type = | Q20: =Config!C5 -> Model A
O21: Index Width = | Q21: {=_xlfn.IFS(Q20=N3,N2,Q20=O3,O2,Q20=P3,P2,Q20=Q3,Q2,Q20=R3,R2,Q20=S3,S2,Q20=T3,T2)} -> 1
O22: Door SQF = | Q22: {=INDEX(N5:T16,Q19,Q21)} -> 6.6666667 | R22: SQF
Q23: =Config!C7 -> 96 | R23: in
O24: Fractional Height Limit = | Q24: {=_xlfn.IFS(Q23<=D53,E53,Q23<=D54,E54,Q23<=D55,E55,Q23<=D56,E56)} -> 1
P25: Quantity Frames = | Q25: =Config!F5 -> 100
P26: Quantity Doors = | Q26: =_xlfn.XLOOKUP(Q20,B30:B36,D30:D36,"ERROR")*Q25 -> 100
P27: Total SQF Width = | Q27: =Q22*Q26 -> 666.66667 | R27: SQF
B29: Locker Models | C29: Fractional Openings | D29: Doors per Frame
B30: Model A | C30: 1 | D30: 1
B31: Model Z | C31: 0.5 | D31: 2
B32: Model B | C32: 0.5 | D32: 2
B33: Model C | C33: 0.33333333 | D33: 3
B34: Model D | C34: 0.25 | D34: 4
B35: Model E | C35: 0.2 | D35: 5
B36: Model F | C36: 0.16666667 | D36: 6
B38: Lower Limit (in) | C38: Door Width | D38: Upper Limit (in) | E38: Fractional Width Limit
B39: 0 | D39: =$B$2*E39 -> 4 | E39: =1/15 -> 0.066666667 | F39: (1/15) | K39: FWL_Coll | L39: [ | M39: ] | N39: ["LL"]
B40: =D39+0.000001 -> 4.000001 | D40: =$B$2*E40 -> 5 | E40: =1/12 -> 0.083333333 | F40: (1/12)
B41: =D40+0.000001 -> 5.000001 | D41: =$B$2*E41 -> 6 | E41: 0.1 | F41: (1/10)
B42: =D41+0.000001 -> 6.000001 | D42: =$B$2*E42 -> 6.6666667 | E42: =1/9 -> 0.11111111 | F42: (1/9)
B43: =D42+0.000001 -> 6.6666677 | D43: =$B$2*E43 -> 7.5 | E43: =1/8 -> 0.125 | F43: (1/8) | O43: 0.25 | P43: =_xlfn.CONCAT("=",O43) -> =0.25
...

Sheet Model Types
A1: Model A
A2: Model Z
A3: Model B
A4: Model C
A5: Model D
A6: Model E
A7: Model F

Sheet Error Analysis
A1: Door W (in) | B1: Door L (in) | C1: Door SQF | D1: Locker QTY Total SQF | E1: Sheet Demand | G1: Locker W (in) | H1: Locker H (in) | I1: Sheets Demand | K1: Current Syteline Error %
A2: =G2-(1/16)*2 -> 9.875 | B2: =(H2-(1/16)*4)/2 -> 35.875 | C2: =A2*B2/144 -> 2.460178 | D2: =C2*Config!$F$2*2 -> 0 | E2: =D2/32 -> 0 | G2: 10 | H2: 72 | I2: 25 | K2: =(Table2[[#This Row],[Sheets Demand]]-Table1[[#This Row],[Sheet Demand]])/Table2[[#This Row],[Sheets Demand]] -> 1
A3: =G3-(1/16)*2 -> 10.875 | B3: =(H3-(1/16)*4)/2 -> 35.875 | C3: =A3*B3/144 -> 2.7093099 | D3: =C3*Config!$F$2*2 -> 0 | E3: =D3/32 -> 0 | G3: 11 | H3: 72 | I3: 25 | K3: =(Table2[[#This Row],[Sheets Demand]]-Table1[[#This Row],[Sheet Demand]])/Table2[[#This Row],[Sheets Demand]] -> 1
A4: =G4-(1/16)*2 -> 11.875 | B4: =(H4-(1/16)*4)/2 -> 35.875 | C4: =A4*B4/144 -> 2.9584418 | D4: =C4*Config!$F$2*2 -> 0 | E4: =D4/32 -> 0 | G4: 12 | H4: 72 | I4: 25 | K4: =(Table2[[#This Row],[Sheets Demand]]-Table1[[#This Row],[Sheet Demand]])/Table2[[#This Row],[Sheets Demand]] -> 1
A5: =G5-(1/16)*2 -> 12.875 | B5: =(H5-(1/16)*4)/2 -> 35.875 | C5: =A5*B5/144 -> 3.2075738 | D5: =C5*Config!$F$2*2 -> 0 | E5: =D5/32 -> 0 | G5: 13 | H5: 72 | I5: 25 | K5: =(Table2[[#This Row],[Sheets Demand]]-Table1[[#This Row],[Sheet Demand]])/Table2[[#This Row],[Sheets Demand]] -> 1
A6: =G6-(1/16)*2 -> 13.875 | B6: =(H6-(1/16)*4)/2 -> 35.875 | C6: =A6*B6/144 -> 3.4567057 | D6: =C6*Config!$F$2*2 -> 0 | E6: =D6/32 -> 0 | G6: 14 | H6: 72 | I6: 25 | K6: =(Table2[[#This Row],[Sheets Demand]]-Table1[[#This Row],[Sheet Demand]])/Table2[[#This Row],[Sheets Demand]] -> 1
A7: =G7-(1/16)*2 -> 14.875 | B7: =(H7-(1/16)*4)/2 -> 35.875 | C7: =A7*B7/144 -> 3.7058377 | D7: =C7*Config!$F$2*2 -> 0 | E7: =D7/32 -> 0 | G7: 15 | H7: 72 | I7: 25 | K7: =(Table2[[#This Row],[Sheets Demand]]-Table1[[#This Row],[Sheet Demand]])/Table2[[#This Row],[Sheets Demand]] -> 1
A8: =G8-(1/16)*2 -> 15.875 | B8: =(H8-(1/16)*4)/2 -> 35.875 | C8: =A8*B8/144 -> 3.9549696 | D8: =C8*Config!$F$2*2 -> 0 | E8: =D8/32 -> 0 | G8: 16 | H8: 72 | I8: 25 | K8: =(Table2[[#This Row],[Sheets Demand]]-Table1[[#This Row],[Sheet Demand]])/Table2[[#This Row],[Sheets Demand]] -> 1
A9: =G9-(1/16)*2 -> 16.875 | B9: =(H9-(1/16)*4)/2 -> 35.875 | C9: =A9*B9/144 -> 4.2041016 | D9: =C9*Config!$F$2*2 -> 0 | E9: =D9/32 -> 0 | G9: 17 | H9: 72 | I9: 50 | K9: =(Table2[[#This Row],[Sheets Demand]]-Table1[[#This Row],[Sheet Demand]])/Table2[[#This Row],[Sheets Demand]] -> 1
A10: =G10-(1/16)*2 -> 17.875 | B10: =(H10-(1/16)*4)/2 -> 35.875 | C10: =A10*B10/144 -> 4.4532335 | D10: =C10*Config!$F$2*2 -> 0 | E10: =D10/32 -> 0 | G10: 18 | H10: 72 | I10: 50 | K10: =(Table2[[#This Row],[Sheets Demand]]-Table1[[#This Row],[Sheet Demand]])/Table2[[#This Row],[Sheets Demand]] -> 1
A11: =G11-(1/16)*2 -> 18.875 | B11: =(H11-(1/16)*4)/2 -> 35.875 | C11: =A11*B11/144 -> 4.7023655 | D11: =C11*Config!$F$2*2 -> 0 | E11: =D11/32 -> 0 | G11: 19 | H11: 72 | I11: 50 | K11: =(Table2[[#This Row],[Sheets Demand]]-Table1[[#This Row],[Sheet Demand]])/Table2[[#This Row],[Sheets Demand]] -> 1
A12: =G12-(1/16)*2 -> 19.875 | B12: =(H12-(1/16)*4)/2 -> 35.875 | C12: =A12*B12/144 -> 4.9514974 | D12: =C12*Config!$F$2*2 -> 0 | E12: =D12/32 -> 0 | G12: 20 | H12: 72 | I12: 50 | K12: =(Table2[[#This Row],[Sheets Demand]]-Table1[[#This Row],[Sheet Demand]])/Table2[[#This Row],[Sheets Demand]] -> 1
A13: =G13-(1/16)*2 -> 20.875 | B13: =(H13-(1/16)*4)/2 -> 35.875 | C13: =A13*B13/144 -> 5.2006293 | D13: =C13*Config!$F$2*2 -> 0 | E13: =D13/32 -> 0 | G13: 21 | H13: 72 | I13: 50 | K13: =(Table2[[#This Row],[Sheets Demand]]-Table1[[#This Row],[Sheet Demand]])/Table2[[#This Row],[Sheets Demand]] -> 1
... A16: =G16-(1/16)*2 -> 23.875 | B16: =(H16-(1/16)*4)/2 -> 35.875 | C16: =A16*B16/144 -> 5.9480252 | D16: =C16*Config!$F$2*2 -> 0 | E16: =D16/32 -> 0 | G16: 24 | H16: 72 | I16: 50 | K16: =(Table2[[#This Row],[Sheets Demand]]-Table1[[#This Row],[Sheet Demand]])/Table2[[#This Row],[Sheets Demand]] -> 1

Sheet Scratch
M3: 60
O4: Stock Size*FWL
B5: Lower Limit (in) | C5: Door Width | D5: Upper Limit (in) | E5: Fractional Width Limit | L5: IndexW | M5: LL | O5: UL | P5: FWL
B6: 0 | D6: 4 | E6: 0.066666667 | F6: (1/15) | L6: 0 | M6: 0 | P6: 0.066666667 | R6: =_xlfn.CONCAT("=",P6) -> =0.0666666666666667
B7: 4.000001 | D7: 5 | E7: 0.083333333 | F7: (1/12) | L7: 1 | P7: 0.083333333 | R7: =_xlfn.CONCAT("=",P7) -> =0.0833333333333333
B8: 5.000001 | D8: 6 | E8: 0.1 | F8: (1/10) | L8: 2 | P8: 0.1 | R8: =_xlfn.CONCAT("=",P8) -> =0.1
B9: 6.000001 | D9: 6.6666667 | E9: 0.11111111 | F9: (1/9) | L9: 3 | P9: 0.11111111 | R9: =_xlfn.CONCAT("=",P9) -> =0.111111111111111
B10: 6.6666677 | D10: 7.5 | E10: 0.125 | F10: (1/8) | L10: 4 | P10: 0.125 | R10: =_xlfn.CONCAT("=",P10) -> =0.125
B11: 7.500001 | D11: 8.5714286 | E11: 0.14285714 | F11: (1/7) | L11: 5 | P11: 0.14285714 | R11: =_xlfn.CONCAT("=",P11) -> =0.142857142857143
B12: 8.5714296 | D12: 10 | E12: 0.16666667 | F12: (1/6) | L12: 6 | P12: 0.16666667 | R12: =_xlfn.CONCAT("=",P12) -> =0.166666666666667
B13: 10.000001 | D13: 12 | E13: 0.2 | F13: (1/5) | L13: 7 | P13: 0.2 | R13: =_xlfn.CONCAT("=",P13) -> =0.2
B14: 12.000001 | D14: 15 | E14: 0.25 | F14: (1/4) | L14: 8 | P14: 0.25 | R14: =_xlfn.CONCAT("=",P14) -> =0.25
B15: 15.000001 | D15: 20 | E15: 0.33333333 | F15: (1/3) | L15: 6 | P15: 0.33333333 | R15: =_xlfn.CONCAT("=",P15) -> =0.333333333333333
B16: 20.000001 | D16: 30 | E16: 0.5 | F16: (1/2) | L16: 10 | P16: 0.5 | R16: =_xlfn.CONCAT("=",P16) -> =0.5
B17: 30.000001 | D17: 60 | E17: 1 | F17: (1) | L17: 11 | M17: SW | P17: 1 | R17: =_xlfn.CONCAT("=",P17) -> =1
L22: FHL_Coll | M22: [ | N22: ] | O22: ["FHL"] | P22: =_xlfn.CONCAT(L22,M22,L6,N22,O22) -> FHL_Coll[0]["FHL"] | Q22: =_xlfn.CONCAT("=",L22,M22,L6,N22,O22) -> =FHL_Coll[0]["FHL"] | T22: FHL_Coll[IndexH]["LL"]
L23: FHL_Coll | M23: [ | N23: ] | O23: ["FHL"] | P23: =_xlfn.CONCAT(L23,M23,L7,N23,O23) -> FHL_Coll[1]["FHL"] | Q23: =_xlfn.CONCAT("=",L23,M23,L7,N23,O23) -> =FHL_Coll[1]["FHL"]
L24: FHL_Coll | M24: [ | N24: ] | O24: ["FHL"] | P24: =_xlfn.CONCAT(L24,M24,L8,N24,O24) -> FHL_Coll[2]["FHL"] | Q24: =_xlfn.CONCAT("=",L24,M24,L8,N24,O24) -> =FHL_Coll[2]["FHL"]
L25: FHL_Coll | M25: [ | N25: ] | O25: ["FHL"] | P25: =_xlfn.CONCAT(L25,M25,L9,N25,O25) -> FHL_Coll[3]["FHL"] | Q25: =_xlfn.CONCAT("=",L25,M25,L9,N25,O25) -> =FHL_Coll[3]["FHL"]
L26: FHL_Coll | M26: [ | N26: ] | O26: ["FHL"] | P26: =_xlfn.CONCAT(L26,M26,L10,N26,O26) -> FHL_Coll[4]["FHL"] | Q26: =_xlfn.CONCAT("=",L26,M26,L10,N26,O26) -> =FHL_Coll[4]["FHL"]
L27: FHL_Coll | M27: [ | N27: ] | O27: ["FHL"] | P27: =_xlfn.CONCAT(L27,M27,L11,N27,O27) -> FHL_Coll[5]["FHL"] | Q27: =_xlfn.CONCAT("=",L27,M27,L11,N27,O27) -> =FHL_Coll[5]["FHL"]
L28: FHL_Coll | M28: [ | N28: ] | O28: ["FHL"] | P28: =_xlfn.CONCAT(L28,M28,L12,N28,O28) -> FHL_Coll[6]["FHL"] | Q28: =_xlfn.CONCAT("=",L28,M28,L12,N28,O28) -> =FHL_Coll[6]["FHL"]
L29: FHL_Coll | M29: [ | N29: ] | O29: ["FHL"] | P29: =_xlfn.CONCAT(L29,M29,L13,N29,O29) -> FHL_Coll[7]["FHL"] | Q29: =_xlfn.CONCAT("=",L29,M29,L13,N29,O29) -> =FHL_Coll[7]["FHL"]
L30: FHL_Coll | M30: [ | N30: ] | O30: ["FHL"] | P30: =_xlfn.CONCAT(L30,M30,L14,N30,O30) -> FHL_Coll[8]["FHL"] | Q30: =_xlfn.CONCAT("=",L30,M30,L14,N30,O30) -> =FHL_Coll[8]["FHL"]
L31: FHL_Coll | M31: [ | N31: ] | O31: ["FHL"] | P31: =_xlfn.CONCAT(L31,M31,L15,N31,O31) -> FHL_Coll[6]["FHL"] | Q31: =_xlfn.CONCAT("=",L31,M31,L15,N31,O31) -> =FHL_Coll[6]["FHL"]
L32: FHL_Coll | M32: [ | N32: ] | O32: ["FHL"] | P32: =_xlfn.CONCAT(L32,M32,L16,N32,O32) -> FHL_Coll[10]["FHL"] | Q32: =_xlfn.CONCAT("=",L32,M32,L16,N32,O32) -> =FHL_Coll[10]["FHL"]
L33: FHL_Coll | M33: [ | N33: ] | O33: ["FHL"] | P33: =_xlfn.CONCAT(L33,M33,L17,N33,O33) -> FHL_Coll[11]["FHL"] | Q33: =_xlfn.CONCAT("=",L33,M33,L17,N33,O33) -> =FHL_Coll[11]["FHL"]
